Workbook
Name CIQWBGuid: "e778162b-a8f3-4f2e-935f-34d73fb7e972"
Name CIQWBGuid: "eeeac8b3-2cb4-40c8-a5e7-67bd1e29d27d"
Name CIQWBInfo: "{ ""CIQVersion"":""9.51.3510.3078"" }"
Name CurrentPrice: #REF!
Name Gross_Profit: '[1]Advanced Financial Analysis'!$9:$9
Name IFF_Price: #REF!
Name IQ_CH: 110000
Name IQ_CQ: 5000
Name IQ_CY: 10000
Name IQ_DAILY: 500000
Name IQ_DNTM: 700000
Name IQ_FH: 100000
Name IQ_FQ: 500
Name IQ_FWD_CY: 10001
Name IQ_FWD_CY1: 10002
Name IQ_FWD_CY2: 10003
Name IQ_FWD_FY: 1001
Name IQ_FWD_FY1: 1002
Name IQ_FWD_FY2: 1003
Name IQ_FWD_Q: 501
Name IQ_FWD_Q1: 502
Name IQ_FWD_Q2: 503
Name IQ_FY: 1000
Name IQ_LATESTK: 1000
Name IQ_LATESTQ: 500
Name IQ_LTM: 2000
Name IQ_LTMMONTH: 120000
Name IQ_MONTH: 15000
Name IQ_MTD: 800000
Name IQ_NAMES_REVISION_DATE_: 45318.8008796296
Name IQ_NTM: 6000
Name IQ_QTD: 750000
Name IQ_TODAY: 0
Name IQ_WEEK: 50000
Name IQ_YTD: 3000
Name IQ_YTDMONTH: 130000
Name Sensitivity: '[1]Advanced Financial Analysis'!$D$49
Name SG_A: '[1]Advanced Financial Analysis'!$11:$11
Name TargetCurrentPrice: #REF!
Name TargetDilutedShares: #REF!

Sheet Assumptions
C2: First Solar
C3: Assumptions
C4: Active Case: | D4: 1
C6: £ In Millions, Unless Otherwise Noted
F7: Historical Years | I7: Forecasted Years
F8: 2021A | G8: 2022A | H8: 2023A | I8: 2024A | J8: 2025A | K8: 2026E | L8: 2027E | M8: 2028E
C10: Products Revenue | F10: ='Three Statement Model'!D31 -> 8.3 | G10: ='Three Statement Model'!E31 -> 8.2 | H10: ='Three Statement Model'!F31 -> 30.5 | I10: ='Three Statement Model'!G31 -> 11.9 | J10: ='Three Statement Model'!H31 -> 78 | K10: 102.2 | L10: 123 | M10: 130.38
C11: % Growth | G11: =(G10-F10)/F10 -> -0.012048193 | H11: =(H10-G10)/G10 -> 2.7195122 | I11: =(I10-H10)/H10 -> -0.60983607 | J11: =(J10-I10)/I10 -> 5.5546218 | K11: =(K10-J10)/J10 -> 0.31025641 | L11: =(L10-K10)/K10 -> 0.2035225 | M11: =(M10-L10)/L10 -> 0.06 | N11: 2026 forecast based on H1 revenue of 51.1m and guidance of continued strenght
C14: Cost of Goods Sold | F14: =-'Three Statement Model'!D32 -> 5.1 | G14: =-'Three Statement Model'!E32 -> 5.5 | H14: =-'Three Statement Model'!F32 -> 19.5 | I14: =-'Three Statement Model'!G32 -> 8.5 | J14: =-'Three Statement Model'!H32 -> 54.1 | K14: =K10*(K15) -> 68.985 | L14: =L10*(L15) -> 79.95 | M14: =M10*(M15) -> 84.747
C15: % of Products Revenue | F15: =F14/F10 -> 0.61445783 | G15: =G14/G10 -> 0.67073171 | H15: =H14/H10 -> 0.63934426 | I15: ='Three Statement Model'!G32/'Three Statement Model'!G31*-1 -> 0.71428571 | J15: ='Three Statement Model'!H32/'Three Statement Model'!H31*-1 -> 0.69358974 | K15: =+OFFSET(K15,$D$4,) -> 0.675 | L15: =+OFFSET(L15,$D$4,) -> 0.65 | M15: =+OFFSET(M15,$D$4,) -> 0.65
C16: Base | K16: 0.675 | L16: 0.65 | M16: 0.65
C17: Bull | K17: 0.6 | L17: 0.6 | M17: 0.6
C18: Bear | K18: 0.7 | L18: 0.7 | M18: 0.7
C20: SG&A Expense | F20: ='Three Statement Model'!D35 -> 5.8 | G20: ='Three Statement Model'!E35 -> 6.5 | H20: ='Three Statement Model'!F35 -> 8.3 | I20: ='Three Statement Model'!G35 -> 11.3 | J20: ='Three Statement Model'!H35 -> 14.8 | K20: =K21*(K10) -> 20.44 | L20: =L21*(L10) -> 21.525 | M20: =M21*(M10) -> 19.557
C21: % of Revenue | F21: =F20/F10 -> 0.69879518 | G21: =G20/G10 -> 0.79268293 | H21: =H20/H10 -> 0.27213115 | I21: =I20/I10 -> 0.94957983 | J21: =J20/J10 -> 0.18974359 | K21: =+OFFSET(K21,$D$4,) -> 0.2 | L21: =+OFFSET(L21,$D$4,) -> 0.175 | M21: =+OFFSET(M21,$D$4,) -> 0.15
C22: Base | K22: 0.2 | L22: 0.175 | M22: 0.15
C23: Bull | K23: 0.15 | L23: 0.125 | M23: 0.1
C24: Bear | K24: 0.2 | L24: 0.2 | M24: 0.2
C27: Depreciation & Amort | F27: ='Three Statement Model'!D106 -> 0.5 | G27: ='Three Statement Model'!E106 -> 0.5 | H27: ='Three Statement Model'!F106 -> 0.5 | I27: ='Three Statement Model'!G106 -> 0.4 | J27: ='Three Statement Model'!H106 -> 0.5 | K27: =K28*K10 -> 0.6132 | L27: =L28*L10 -> 0.738 | M27: =M28*M10 -> 0.78228
C28: % of Revenue | F28: =F27/F10 -> 0.060240964 | G28: =G27/G10 -> 0.06097561 | H28: =H27/H10 -> 0.016393443 | I28: =I27/I10 -> 0.033613445 | J28: =J27/J10 -> 0.0064102564 | K28: =+OFFSET(K28,$D$4,) -> 0.006 | L28: =+OFFSET(L28,$D$4,) -> 0.006 | M28: =+OFFSET(M28,$D$4,) -> 0.006
C29: Base | K29: 0.006 | L29: 0.006 | M29: 0.006
C30: Bull | K30: 0.004 | L30: 0.004 | M30: 0.004
C31: Bear | K31: 0.01 | L31: 0.01 | M31: 0.01
C33: Other Operating Expense | F33: ='Three Statement Model'!D38 -> 0 | G33: ='Three Statement Model'!E38 -> 0 | H33: ='Three Statement Model'!F38 -> 0 | I33: ='Three Statement Model'!G38 -> 0 | J33: ='Three Statement Model'!H38 -> 0 | K33: =K34*K10 -> 0 | L33: =L34*L10 -> 0 | M33: =M34*M10 -> 0
C34: % of Revenue | F34: =F33/(F10) -> 0 | G34: =G33/(G10) -> 0 | H34: =H33/(H10) -> 0 | I34: =I33/(I10) -> 0 | J34: =J33/(J10) -> 0 | K34: =+OFFSET(K34,$D$4,) -> 0 | L34: =+OFFSET(L34,$D$4,) -> 0 | M34: =+OFFSET(M34,$D$4,) -> 0
C35: Base | K35: 0 | L35: 0 | M35: 0
C36: Bull | K36: 0 | L36: 0 | M36: 0
C37: Bear | K37: 0.005 | L37: 0.005 | M37: 0.005
C39: Other Non-Operating Inc. | F39: =-'Three Statement Model'!D49 -> 0 | G39: =-'Three Statement Model'!E49 -> 0 | H39: =-'Three Statement Model'!F49 -> 0 | I39: =-'Three Statement Model'!G49 -> 0 | J39: =-'Three Statement Model'!H49 -> -3.4 | K39: =K40*K10 -> 0 | L39: =L40*L10 -> 0 | M39: =M40*M10 -> 0
C40: % of Revenue | F40: =F39/(F10) -> 0 | G40: =G39/(G10) -> 0 | H40: =H39/(H10) -> 0 | I40: =I39/(I10) -> 0 | J40: =J39/(J10) -> -0.043589744 | K40: =+OFFSET(K40,$D$4,) -> 0 | L40: =+OFFSET(L40,$D$4,) -> 0 | M40: =+OFFSET(M40,$D$4,) -> 0
C41: Base | K41: 0 | L41: 0 | M41: 0
C42: Bull | K42: 0 | L42: 0 | M42: 0
C43: Bear | K43: 0 | L43: 0 | M43: 0
C45: Accounts Receivable | F45: ='Three Statement Model'!D64 -> 2.3 | G45: ='Three Statement Model'!E64 -> 1.7 | H45: ='Three Statement Model'!F64 -> 3.3 | I45: ='Three Statement Model'!G64 -> 2.1 | J45: ='Three Statement Model'!H64 -> 50.8 | K45: =(K46*K10/365) -> 56 | L45: =(L46*L10/365) -> 67.39726 | M45: =(M46*M10/365) -> 71.441096
C46: Accounts Receivable Days | F46: =(F45/(F10))*365 -> 101.14458 | G46: =(G45/(G10))*365 -> 75.670732 | H46: =(H45/(H10))*365 -> 39.491803 | I46: =(I45/(I10))*365 -> 64.411765 | J46: =(J45/(J10))*365 -> 237.71795 | K46: =+OFFSET(K46,$D$4,) -> 200 | L46: =+OFFSET(L46,$D$4,) -> 200 | M46: =+OFFSET(M46,$D$4,) -> 200
C47: Base | K47: 200 | L47: 200 | M47: 200
C48: Bull | K48: 250 | L48: 250 | M48: 250
C49: Bear | K49: 175 | L49: 175 | M49: 150
C52: Long-Term Investments | F52: ='Three Statement Model'!D75 -> 9 | G52: ='Three Statement Model'!E75 -> 9.3 | H52: ='Three Statement Model'!F75 -> 11.7 | I52: ='Three Statement Model'!G75 -> 14.1 | J52: ='Three Statement Model'!H75 -> 16.7 | K52: =(K10*K53) -> 15.33 | L52: =(L10*L53) -> 15.375 | M52: =(M10*M53) -> 13.038
C53: % of Revenue | F53: =F52/(F10) -> 1.0843373 | G53: =G52/(G10) -> 1.1341463 | H53: =H52/(H10) -> 0.38360656 | I53: =I52/(I10) -> 1.1848739 | J53: =J52/(J10) -> 0.21410256 | K53: =+OFFSET(K53,$D$4,) -> 0.15 | L53: =+OFFSET(L53,$D$4,) -> 0.125 | M53: =+OFFSET(M53,$D$4,) -> 0.1
...

Sheet Metrics & Drivers
B2: Metrics & Drivers | G2: Case
B3: $ in millions, unless otherwise noted | G3: =#REF! -> #REF!
B5: For Fiscal Year Ending | F5: 2021 | G5: =F5+1 -> 2022 | H5: =G5+1 -> 2023 | I5: =H5+1 -> 2024 | J5: =I5+1 -> 2025 | K5: =J5+1 -> 2026 | L5: =K5+1 -> 2027 | M5: =L5+1 -> 2028
A7: x | B7: Revenue Build
B9: Revenue
B10: % of revenue | I10: =OFFSET(I37,$G$3,0)
B11: Base
B12: Bull
B13: Bear
B15: Modules Sold per year
B16: % Growth | I16: =OFFSET(I37,$G$3,0)
B17: Base
B18: Bull
B19: Bear
A34: x | B34: Other Metrics & Drivers
B36: Cost of Goods Sold
B37: % of revenue | I37: =OFFSET(I37,$G$3,0)
B38: Base
B39: Bull
B40: Bear
B42: SG&A Expense
B43: % of revenue
B44: Base
B45: Bull
B46: Bear
B48: D&A Expense
B49: % of capex
B50: Base
B51: Bull
... B130: Bear

Sheet Additional Schedules
B2: Additional Schedules
B3: $ in millions, unless otherwise noted
B5: For Fiscal Year Ending | F5: 2021 | G5: =F5+1 -> 2022 | H5: =G5+1 -> 2023 | I5: =H5+1 -> 2024 | J5: =I5+1 -> 2025 | K5: =J5+1 -> 2026 | L5: =K5+1 -> 2027 | M5: =L5+1 -> 2028
B7: Net Working Capital
B9: Current Operating Asset 1
B10: Current Operating Asset 2
B11: Current Operating Asset 3
B12: Current Operating Asset 4
B13: Total Current Operating Assets
B15: Current Operating Liability 1
B16: Current Operating Liability 2
B17: Current Operating Liability 3
B18: Current Operating Liability 4
B19: Total Current Operating Liabilities
B21: Net Working Capital
B22: Change in Net Working Capital

Sheet Three Statement Model
B5: Assumptions & Drivers
B7: All figures in USD Millions unless stated | D7: 2021A | E7: 2022A | F7: 2023A | G7: 2024A | H7: 2025A | I7: 2026E | J7: 2027E | K7: 2028E
B9: Days in Period | D9: 365 | E9: 365 | F9: 365 | G9: =365+1 -> 366 | H9: 365 | I9: 365 | J9: 365 | K9: =365+1 -> 366
B11: Income Statement
B12: Sales Growth | E12: =E31/D31-1 -> -0.012048193 | F12: =F31/E31-1 -> 2.7195122 | G12: =G31/F31-1 -> -0.60983607 | H12: =H31/G31-1 -> 5.5546218 | I12: =Assumptions!K11 -> 0.31025641 | J12: =Assumptions!L11 -> 0.2035225 | K12: =Assumptions!M11 -> 0.06
B13: Gross Margin | D13: =D33/D31 -> 0.38554217 | E13: =E33/E31 -> 0.32926829 | F13: =F33/F31 -> 0.36065574 | G13: =G33/G31 -> 0.28571429 | H13: =H33/H31 -> 0.30641026 | I13: =(1-Assumptions!K15) -> 0.325 | J13: =(1-Assumptions!L15) -> 0.35 | K13: =(1-Assumptions!M15) -> 0.35
B14: SG&A | D14: =D35 -> 5.8 | E14: =E35 -> 6.5 | F14: =F35 -> 8.3 | G14: =G35 -> 11.3 | H14: =H35 -> 14.8 | I14: =Assumptions!K21*Assumptions!K10 -> 20.44 | J14: =Assumptions!L21*Assumptions!L10 -> 21.525 | K14: =Assumptions!M21*Assumptions!M10 -> 19.557
B15: Capital Expenditure % of Revenue | D15: =D117/D31*-1 -> 0.036144578 | E15: =E117/E31*-1 -> 0.024390244 | F15: =F117/F31*-1 -> 0.006557377 | G15: =G117/G31*-1 -> 0.016806723 | H15: =H117/H31*-1 -> 0.0064102564 | I15: =Assumptions!K65 -> 0.015 | J15: =Assumptions!L65 -> 0.015 | K15: =Assumptions!M65 -> 0.015
B16: Interest Expense % of Revenue | D16: =D43/D31 -> -0.072289157 | E16: =E43/E31 -> -0.073170732 | F16: =F43/F31 -> -0.026229508 | G16: =G43/G31 -> -0.084033613 | H16: =H43/H31 -> -0.024358974 | I16: =-Assumptions!K94 -> -0.0125 | J16: =-Assumptions!L94 -> -0.0125 | K16: =-Assumptions!M94 -> -0.0125
B17: Depreciation (Percent of Sales) | D17: =D106/D31 -> 0.060240964 | E17: =E106/E31 -> 0.06097561 | F17: =F106/F31 -> 0.016393443 | G17: =G106/G31 -> 0.033613445 | H17: =H106/H31 -> 0.0064102564 | I17: =Assumptions!K28 -> 0.006 | J17: =Assumptions!L28 -> 0.006 | K17: =Assumptions!M28 -> 0.006
B18: Tax Rate (Percent of EBT) | D18: =D52/D47*-1 -> -0.13333333 | E18: =E52/E47*-1 -> -0.14925373 | F18: =F52/F47*-1 -> -1 | G18: =G52/G47*-1 -> -0.051724138 | H18: =H52/H47*-1 -> 0.125 | I18: =Assumptions!K76 -> 0.13 | J18: =Assumptions!L76 -> 0.15 | K18: =Assumptions!M76 -> 0.16
B20: Balance Sheet
B21: Capital Asset Turnover Ratio | C21: (x) | D21: =D31/D73 -> 4.8823529 | E21: =E31/E73 -> 6.3076923 | F21: =F31/F73 -> 25.416667 | G21: =G31/G73 -> 10.818182 | H21: =H31/H73 -> 55.714286 | I21: =I31/I73 -> 67.771883 | J21: =J31/J73 -> 76.012261 | K21: =K31/K73 -> 75.341377
B22: Receivable Days (Sales Basis) | C22: (Days) | D22: =Assumptions!F46 -> 101.14458 | E22: =Assumptions!G46 -> 75.670732 | F22: =Assumptions!H46 -> 39.491803 | G22: =Assumptions!I46 -> 64.411765 | H22: =Assumptions!J46 -> 237.71795 | I22: =Assumptions!K46 -> 200 | J22: =Assumptions!L46 -> 200 | K22: =Assumptions!M46 -> 200
B23: Inventory Days (COGS Basis) | C23: (Days) | D23: =D65/-D32*D9 -> 171.76471 | E23: =E65/-E32*E9 -> 159.27273 | F23: =F65/-F32*F9 -> 65.512821 | G23: =G65/-G32*G9 -> 348.77647 | H23: =H65/-H32*H9 -> 27.661738 | I23: =I65/-I32*I9 -> 26.455026 | J23: =J65/-J32*J9 -> 22.826767 | K23: =K65/-K32*K9 -> 21.593685
B24: Payable Days (COGS Basis) | C24: (Days) | D24: =Assumptions!F59 -> 43.975904 | E24: =Assumptions!G59 -> 66.768293 | F24: =Assumptions!H59 -> 29.918033 | G24: =Assumptions!I59 -> 73.613445 | H24: =Assumptions!J59 -> 24.333333 | I24: =Assumptions!K59 -> 30 | J24: =Assumptions!L59 -> 30 | K24: =Assumptions!M59 -> 30
B25: Long Term Debt | D25: =D86 -> 0 | E25: =E86 -> 0.3 | F25: =F86 -> 0 | G25: =G86 -> 3 | H25: =H86 -> 3 | I25: =I86 -> 3 | J25: =J86 -> 3 | K25: =K86 -> 3
B27: Income Statement
B29: All figures in USD Millions unless stated | D29: =D$7 -> 2021A | E29: =E$7 -> 2022A | F29: =F$7 -> 2023A | G29: =G$7 -> 2024A | H29: =H$7 -> 2025A | I29: =I$7 -> 2026E | J29: =J$7 -> 2027E | K29: =K$7 -> 2028E
B31: Total Revenue | D31: 8.3 | E31: 8.2 | F31: 30.5 | G31: 11.9 | H31: 78 | I31: =H31*(1+I12) -> 102.2 | J31: =I31*(1+J12) -> 123 | K31: =J31*(1+K12) -> 130.38
B32: Cost Of Goods Sold | D32: -5.1 | E32: -5.5 | F32: -19.5 | G32: -8.5 | H32: -54.1 | I32: =-Assumptions!K14 -> -68.985 | J32: =-Assumptions!L14 -> -79.95 | K32: =-Assumptions!M14 -> -84.747
B33: Gross Profit | D33: =SUM(D31,D32) -> 3.2 | E33: =SUM(E31,E32) -> 2.7 | F33: =SUM(F31,F32) -> 11 | G33: =SUM(G31,G32) -> 3.4 | H33: =SUM(H31,H32) -> 23.9 | I33: =SUM(I31,I32) -> 33.215 | J33: =SUM(J31,J32) -> 43.05 | K33: =SUM(K31,K32) -> 45.633
B35: Selling General & Admin Exp. | D35: 5.8 | E35: 6.5 | F35: 8.3 | G35: 11.3 | H35: 14.8 | I35: =Assumptions!K20 -> 20.44 | J35: =Assumptions!L20 -> 21.525 | K35: =Assumptions!M20 -> 19.557
B36: Depreciation & Amort. | D36: 0 | E36: 0 | F36: 0 | G36: 0 | H36: 0 | I36: =Assumptions!K27 -> 0.6132 | J36: =Assumptions!L27 -> 0.738 | K36: =Assumptions!M27 -> 0.78228
B37: Amort. Of Goodwill and Intangibles | D37: 2.3 | E37: 2.2 | F37: 2.4 | G37: 2.7 | H37: 2.7 | I37: 3 | J37: 3.3 | K37: 3.6 | L37: Increase in line with capitalized development expenditure
B38: Other Operating Expenses | D38: 0 | E38: 0 | F38: 0 | G38: 0 | H38: 0 | I38: 0 | J38: 0 | K38: 0 | L38: flatline
B39: Total Operating Expenses | D39: =SUM(D35:D38) -> 8.1 | E39: =SUM(E35:E38) -> 8.7 | F39: =SUM(F35:F38) -> 10.7 | G39: =SUM(G35:G38) -> 14 | H39: =SUM(H35:H38) -> 17.5 | I39: =SUM(I35:I38) -> 24.0532 | J39: =SUM(J35:J38) -> 25.563 | K39: =SUM(K35:K38) -> 23.93928
B41: EBIT (Operating Income) | D41: =D33-D39 -> -4.9 | E41: =E33-E39 -> -6 | F41: =F33-F39 -> 0.3 | G41: =G33-G39 -> -10.6 | H41: =H33-H39 -> 6.4 | I41: =I33-I39 -> 9.1618 | J41: =J33-J39 -> 17.487 | K41: =K33-K39 -> 21.69372
B43: Interest Expense | D43: -0.6 | E43: -0.6 | F43: -0.8 | G43: -1 | H43: -1.9 | I43: =Assumptions!K93 -> 0.67625 | J43: =Assumptions!L93 -> 0.8623125 | K43: =Assumptions!M93 -> 0.999375
B44: Interest and Invest. Income | D44: 0 | E44: 0 | F44: 0 | G44: 0 | H44: 0.3 | I44: 0.3 | J44: 0.3 | K44: 0.3 | L44: flatline
B45: Foreign Currency Loss | D45: -0.5 | E45: -0.1 | F45: -0.2 | G45: 0 | H45: 0 | I45: 0 | J45: 0 | K45: 0 | L45: flatline
B46: Net Interest Exp. | D46: =SUM(D43:D45) -> -1.1 | E46: =SUM(E43:E45) -> -0.7 | F46: =SUM(F43:F45) -> -1 | G46: =SUM(G43:G45) -> -1 | H46: =SUM(H43:H45) -> -1.6 | I46: =-Assumptions!K93 -> -0.67625 | J46: =-Assumptions!L93 -> -0.8623125 | K46: =-Assumptions!M93 -> -0.999375
B47: Earnings Before Taxes | D47: =D41+D46 -> -6 | E47: =E41+E46 -> -6.7 | F47: =F41+F46 -> -0.7 | G47: =G41+G46 -> -11.6 | H47: =H41+H46 -> 4.8 | I47: =I41+I46 -> 8.48555 | J47: =J41+J46 -> 16.624687 | K47: =K41+K46 -> 20.694345
B49: Non-operating Income Expense | D49: 0 | E49: 0 | F49: 0 | G49: 0 | H49: 3.4 | I49: 0 | J49: 0 | K49: 0
B50: EBT Including Unusual Items | D50: =D47-D49 -> -6 | E50: =E47-E49 -> -6.7 | F50: =F47-F49 -> -0.7 | G50: =G47-G49 -> -11.6 | H50: =H47-H49 -> 1.4 | I50: =I47-I49 -> 8.48555 | J50: =J47-J49 -> 16.624687 | K50: =K47-K49 -> 20.694345
B52: Taxes | D52: -0.8 | E52: -1 | F52: -0.7 | G52: -0.6 | H52: -0.6 | I52: =I50*I18 -> 1.1031215 | J52: =J50*J18 -> 2.4937031 | K52: =K50*K18 -> 3.3110952
B53: Net Income | D53: =D50-D52 -> -5.2 | E53: =E50-E52 -> -5.7 | F53: =F50-F52 -> -1.110223e-15 | G53: =G50-G52 -> -11 | H53: =H50-H52 -> 2 | I53: =I50-I52 -> 7.3824285 | J53: =J50-J52 -> 14.130984 | K53: =K50-K52 -> 17.38325
B55: Dividends | D55: 0 | E55: 0 | F55: 0 | G55: 0 | H55: =G55 -> 0 | I55: =H55 -> 0 | J55: =I55 -> 0 | K55: =J55 -> 0
B57: Balance Sheet
B59: All figures in USD Millions unless stated | D59: =D$7 -> 2021A | E59: =E$7 -> 2022A | F59: =F$7 -> 2023A | G59: =G$7 -> 2024A | H59: =H$7 -> 2025A | I59: =I$7 -> 2026E | J59: =J$7 -> 2027E | K59: =K$7 -> 2028E
...

Sheet Sheet2

Sheet DCF
B2: Discounted Cash Flow Analysis
B3: $ in millions, unless otherwise noted | F3: =TODAY() -> 46071
B5: For Fiscal Year Ending | G5: 2025A | H5: 2026 | I5: =H5+1 -> 2027 | J5: =I5+1 -> 2028 | O5: Perpetuity Growth Method
B7: Total Revenues | G7: ='Three Statement Model'!H31 -> 78 | H7: ='Three Statement Model'!I31 -> 102.2 | I7: ='Three Statement Model'!J31 -> 123 | J7: ='Three Statement Model'!K31 -> 130.38 | O7: =$J$5&"E Unlevered Free Cash Flow" -> 2028E Unlevered Free Cash Flow | R7: =J29 -> 31.762989
B8: % growth | H8: =(H7-G7)/G7 -> 0.31025641 | I8: =(I7-H7)/H7 -> 0.2035225 | J8: =(J7-I7)/I7 -> 0.06 | O8: Perpetuity Growth Rate | R8: 0.02
O9: Terminal Value | R9: =(R7*(1+R8))/(D32-R8) -> 386.7555
B10: Cost of Goods Sold | G10: =-'Three Statement Model'!H32 -> 54.1 | H10: =-'Three Statement Model'!I32 -> 68.985 | I10: =-'Three Statement Model'!J32 -> 79.95 | J10: =-'Three Statement Model'!K32 -> 84.747 | O10: Discount Factor | R10: =J34 -> 0.74364393
B11: Gross Profit | G11: =G7-G10 -> 23.9 | H11: =H7-H10 -> 33.215 | I11: =I7-I10 -> 43.05 | J11: =J7-J10 -> 45.633 | O11: Present Value of Terminal Value | R11: =R10*R9 -> 287.60838
B12: % margin | G12: =G11/G7 -> 0.30641026 | H12: =H11/H7 -> 0.325 | I12: =I11/I7 -> 0.35 | J12: =J11/J7 -> 0.35 | O12: Present Value of Cash Flow | R12: =J37 -> 45.765537
O13: Total Enterprise Value | R13: =R12+R11 -> 333.37392
B14: SG&A Expense | G14: ='Three Statement Model'!H35 -> 14.8 | H14: ='Three Statement Model'!I35 -> 20.44 | I14: ='Three Statement Model'!J35 -> 21.525 | J14: ='Three Statement Model'!K35 -> 19.557 | O14: Less: Debt | R14: 17.2
B15: D&A Expense | G15: ='Three Statement Model'!H37 -> 2.7 | H15: ='Three Statement Model'!I37 -> 3 | I15: ='Three Statement Model'!J37 -> 3.3 | J15: ='Three Statement Model'!K37 -> 3.6 | O15: Plus: Cash | R15: 10
B16: Other Operating Expense | G16: ='Three Statement Model'!H36 -> 0 | H16: ='Three Statement Model'!I36 -> 0.6132 | I16: ='Three Statement Model'!J36 -> 0.738 | J16: ='Three Statement Model'!K36 -> 0.78228 | O16: Total Equity Value | R16: =R15-R14+R13 -> 326.17392
B17: EBIT | G17: =G11-SUM(G14:G16) -> 6.4 | H17: =H11-SUM(H14:H16) -> 9.1618 | I17: =I11-SUM(I14:I16) -> 17.487 | J17: =J11-SUM(J14:J16) -> 21.69372 | O17: Diluted Shares Outstanding | R17: 251.6
B18: % margin | G18: =G17/G7 -> 0.082051282 | H18: =H17/H7 -> 0.089645793 | I18: =I17/I7 -> 0.14217073 | J18: =J17/J7 -> 0.1663884 | O18: Implied Share Price | R18: =R16/R17 -> 1.2963987
O19: Upside | R19: =(R18-WACC!E10)/WACC!E10 -> 0.47318036
B20: Taxes | G20: ='Three Statement Model'!H52 -> -0.6 | H20: ='Three Statement Model'!I52 -> 1.1031215 | I20: ='Three Statement Model'!J52 -> 2.4937031 | J20: ='Three Statement Model'!K52 -> 3.3110952
B21: % effective tax rate | G21: =G20/G17 -> -0.09375 | H21: =H20/H17 -> 0.12040445 | I21: =I20/I17 -> 0.14260326 | J21: =J20/J17 -> 0.1526292
B22: Net Operating Profit After Tax | G22: =G17-G20 -> 7 | H22: =H17-H20 -> 8.0586785 | I22: =I17-I20 -> 14.993297 | J22: =J17-J20 -> 18.382625
B23: % margin | G23: =G22/G7 -> 0.08974359 | H23: =H22/H7 -> 0.07885204 | I23: =I22/I7 -> 0.12189672 | J23: =J22/J7 -> 0.14099267
B25: Plus: D&A Expense | G25: =G15 -> 2.7 | H25: =H15 -> 3 | I25: =I15 -> 3.3 | J25: =J15 -> 3.6
B26: Less: Capital Expenditures | G26: =-'Three Statement Model'!H117 -> 0.5 | H26: =-'Three Statement Model'!I117 -> 1.533 | I26: =-'Three Statement Model'!J117 -> 1.845 | J26: =-'Three Statement Model'!K117 -> 1.9557
B27: Less: Change in Net Working Capital | G27: =('Three Statement Model'!H69-'Three Statement Model'!H84) - ('Three Statement Model'!G69-'Three Statement Model'!G84) -> 14.9 | H27: =('Three Statement Model'!I69-'Three Statement Model'!I84) - ('Three Statement Model'!H69-'Three Statement Model'!H84) -> -4.0166988 | I27: =('Three Statement Model'!J69-'Three Statement Model'!J84) - ('Three Statement Model'!I69-'Three Statement Model'!I84) -> 4.4506855 | J27: =('Three Statement Model'!K69-'Three Statement Model'!K84) - ('Three Statement Model'!J69-'Three Statement Model'!J84) -> 11.736064
B28: Less: Stub Period
B29: Unlevered Free Cash Flow | G29: =G22+G25-G26-G27 -> -5.7 | H29: =H22+H25-H26+H27 -> 5.5089797 | I29: =I22+I25-I26+I27 -> 20.898982 | J29: =J22+J25-J26+J27 -> 31.762989
B30: % margin | G30: =G29/G7 -> -0.073076923 | H30: =H29/H7 -> 0.053903911 | I30: =I29/I7 -> 0.16991043 | J30: =J29/J7 -> 0.24361857
B32: WACC | D32: =WACC!$J$23 -> 0.10376933 | G32: =$D$32 -> 0.10376933 | H32: =$D$32 -> 0.10376933 | I32: =$D$32 -> 0.10376933 | J32: =$D$32 -> 0.10376933
B33: Discount Period | G33: 0 | H33: 1 | I33: 2 | J33: 3
B34: Discount Factor | G34: =1/(1+G32)^G33 -> 1 | H34: =1/(1+H32)^H33 -> 0.9059864 | I34: =1/(1+I32)^I33 -> 0.82081136 | J34: =1/(1+J32)^J33 -> 0.74364393
B35: Present Value of Unlevered Free Cash Flow | G35: =G29*G34 -> -5.7 | H35: =H29*H34 -> 4.9910607 | I35: =I29*I34 -> 17.154122 | J35: =J29*J34 -> 23.620354
B37: Sum of Present Value Cash Flows | J37: =SUM(H35:J35) -> 45.765537
B41: DCF Sensitivity Analysis: Upside / (Downside) - Perpetuity Growth Method
D42: Perpetuity Growth
C43: =R16/R17 -> 1.2963987 | D43: 0.0125 | E43: 0.015 | F43: 0.0175 | G43: 0.02 | H43: 0.0225 | I43: 0.025 | J43: 0.0275
B44: WACC | C44: 0.077 | D44: 1.7507311 | E44: 1.8187717 | F44: 1.8925299 | G44: 1.9727582 | H44: 2.0603469 | I44: 2.1563576 | J44: 2.2620663
C45: 0.082 | D45: 1.6141409 | E45: 1.6720353 | F45: 1.7344176 | G45: 1.8018308 | H45: 1.874909 | I45: 1.9543975 | J45: 2.0411785
C46: 0.087 | D46: 1.4959791 | E46: 1.5457761 | F46: 1.5991555 | G46: 1.6565186 | H46: 1.7183283 | I46: 1.7851228 | J46: 1.8575302
C47: =WACC!$J$23 -> 0.10376933 | D47: 1.1947492 | E47: 1.2267239 | F47: 1.2605517 | G47: 1.2963987 | H47: 1.3344511 | I47: 1.374919 | J47: 1.4180398
C48: 0.097 | D48: 1.30185 | E48: 1.3397001 | F48: 1.3799307 | G48: 1.4227736 | H48: 1.468492 | I48: 1.5173852 | J48: 1.5697959
C49: 0.102 | D49: 1.2211657 | E49: 1.2545425 | F49: 1.2898943 | G49: 1.3274017 | H49: 1.3672681 | I49: 1.4097232 | J49: 1.4550276
...

Sheet WACC
B2: Weighted Average Cost of Capital
B3: £ in millions, unless otherwise noted
B5: Inputs | G5: Cost of Debt Calculation
B6: Risk-Free Rate | E6: 0.044
B7: Equity Risk Premium | E7: 0.06 | G7: Risk-Free Rate (10-Year Gilt) | J7: 0.044
B8: Beta* | E8: 1 | G8: Credit Spread on [XXX] Rating
B9: Effective Tax Rate | E9: =J10 -> 0.26 | G9: Pre-Tax Cost of Debt | J9: 8
B10: Current Share Price | E10: 0.88 | G10: Effective Tax Rate (UK Corp Tax 2025) | J10: 0.26
B11: Diluted Shares Outstanding | E11: 251600000 | G11: After-Tax Cost of Debt | J11: =J9*(1+J10)/100 -> 0.1008
B12: Market Value of Debt | E12: 17200000
G13: Cost of Equity Calculation
B14: *5Y Beta = 0.53; more conservative 1.0 used
G15: Risk-Free Rate | J15: =J7 -> 0.044
G16: Equity Risk Premium | J16: =E7 -> 0.06
E17: 16/11/2025 | G17: Beta | J17: =E8 -> 1
G18: Cost of Equity | J18: =J15+J16*J17 -> 0.104
B20: Weighted Average Cost of Capital Calculation | G20: Total Value | I20: % | J20: Cost
B21: Market Value of Debt | G21: =E12 -> 17200000 | I21: =G21/G23 -> 0.072084758 | J21: =J11 -> 0.1008
B22: Market Value of Equity | G22: =E10*E11 -> 221408000 | I22: =G22/G23 -> 0.92791524 | J22: =J18 -> 0.104
B23: Total | G23: =SUM(G21:G22) -> 238608000 | I23: =SUM(I21:I22) -> 1 | J23: =I21*J21+I22*J22 -> 0.10376933

Sheet Presentation Formatting
A1: WACC Calculation
F2: Perpetuity Growth Method
A3: Cost of Debt Calculation | F3: 2028E Unlevered Free Cash Flow | G3: 31.8
A4: Risk-Free Rate (10-Year Gilt) | D4: 0.044 | F4: Perpetuity Growth Rate | G4: 0.02
A5: Pre-Tax Cost of Debt | D5: 8 | F5: Terminal Value | G5: 386.8
A6: Effective Tax Rate (UK Corp Tax 2025) | D6: 0.26 | E6: *5Y Beta = 0.53; more conservative 1.0 used | F6: Discount Factor | G6: 0.74
A7: After-Tax Cost of Debt | D7: 0.1008 | F7: Present Value of Terminal Value | G7: 287.6
F8: Present Value of Cash Flow | G8: 45.8
A9: Cost of Equity Calculation | F9: Total Enterprise Value | G9: 333.4
A10: Risk-Free Rate | D10: 0.044 | F10: Less: Debt | G10: 17.2
A11: Equity Risk Premium | D11: 0.06 | F11: Plus: Cash | G11: 10
A12: Beta | D12: 1 | F12: Total Equity Value | G12: 326.2
A13: Cost of Equity | D13: 0.104 | F13: Diluted Shares Outstanding | G13: 251.6
F14: Implied Share Price | G14: £1.30
A15: WACC Calculation | B15: Total Value | C15: % | D15: Cost | F15: Upside | G15: 0.4732
A16: Market Value of Debt | B16: 17200000 | C16: 0.072084758 | D16: 0.1008
A17: Market Value of Equity | B17: 221408000 | C17: 0.92791524 | D17: 0.104
A18: Total | B18: 238608000 | C18: 1 | D18: 0.10376933
